{"uuid": "36f06139-9b50-440f-a2f6-5238b8f634ec", "children": ["cc281de7-277a-45a7-ac7f-3dff78fa0d03"], "befores": [{"name": "app_driver", "status": "broken", "statusDetails": {"message": "selenium.common.exceptions.WebDriverException: Message: An unknown server-side error occurred while processing the command. Original error: Could not find a connected Android device in 20209ms.\nStacktrace:\nUnknownError: An unknown server-side error occurred while processing the command. Original error: Could not find a connected Android device in 20209ms.\n    at getResponseForW3CError (C:\\Program Files\\Appium Server GUI\\resources\\app\\node_modules\\appium\\node_modules\\appium-base-driver\\lib\\protocol\\errors.js:804:9)\n    at asyncHandler (C:\\Program Files\\Appium Server GUI\\resources\\app\\node_modules\\appium\\node_modules\\appium-base-driver\\lib\\protocol\\protocol.js:380:37)\n", "trace": "  File \"C:\\python\\Lib\\site-packages\\pluggy\\_callers.py\", line 38, in run_old_style_hookwrapper\n    res = yield\n          ^^^^^\n  File \"C:\\python\\Lib\\site-packages\\pluggy\\_callers.py\", line 139, in _multicall\n    teardown.throw(exception)\n    ~~~~~~~~~~~~~~^^^^^^^^^^^\n  File \"C:\\python\\Lib\\site-packages\\pytest_asyncio\\plugin.py\", line 681, in pytest_fixture_setup\n    return (yield)\n            ^^^^^\n  File \"C:\\python\\Lib\\site-packages\\pluggy\\_callers.py\", line 139, in _multicall\n    teardown.throw(exception)\n    ~~~~~~~~~~~~~~^^^^^^^^^^^\n  File \"C:\\python\\Lib\\site-packages\\_pytest\\setuponly.py\", line 36, in pytest_fixture_setup\n    return (yield)\n            ^^^^^\n  File \"C:\\python\\Lib\\site-packages\\pluggy\\_callers.py\", line 121, in _multicall\n    res = hook_impl.function(*args)\n  File \"C:\\python\\Lib\\site-packages\\_pytest\\fixtures.py\", line 1195, in pytest_fixture_setup\n    result = call_fixture_func(fixturefunc, request, kwargs)\n  File \"C:\\python\\Lib\\site-packages\\_pytest\\fixtures.py\", line 922, in call_fixture_func\n    fixture_result = next(generator)\n  File \"E:\\work\\person-test\\simon-ui-automated-test\\conftest.py\", line 33, in app_driver\n    driver = webdriver.Remote(\n        command_executor=AppConfig.APPIUM_SERVER,\n        options=options\n    )\n  File \"C:\\python\\Lib\\site-packages\\appium\\webdriver\\webdriver.py\", line 249, in __init__\n    super().__init__(\n    ~~~~~~~~~~~~~~~~^\n        command_executor=command_executor,\n        ^^^^^^^^^^^^^^^^^^^^^^^^^^^^^^^^^^\n    ...<3 lines>...\n        client_config=client_config,\n        ^^^^^^^^^^^^^^^^^^^^^^^^^^^^\n    )\n    ^\n  File \"C:\\python\\Lib\\site-packages\\selenium\\webdriver\\remote\\webdriver.py\", line 263, in __init__\n    self.start_session(capabilities)\n    ~~~~~~~~~~~~~~~~~~^^^^^^^^^^^^^^\n  File \"C:\\python\\Lib\\site-packages\\appium\\webdriver\\webdriver.py\", line 342, in start_session\n    response = self.execute(RemoteCommand.NEW_SESSION, w3c_caps)\n  File \"C:\\python\\Lib\\site-packages\\selenium\\webdriver\\remote\\webdriver.py\", line 458, in execute\n    self.error_handler.check_response(response)\n    ~~~~~~~~~~~~~~~~~~~~~~~~~~~~~~~~~^^^^^^^^^^\n  File \"C:\\python\\Lib\\site-packages\\selenium\\webdriver\\remote\\errorhandler.py\", line 232, in check_response\n    raise exception_class(message, screen, stacktrace)\n"}, "start": 1761644347439, "stop": 1761644367888}], "start": 1761644347439, "stop": 1761644368106}